Workbook

Sheet 2026
A1: CIUDAD 1132
A2: Gastos 2026 — catálogo de conceptos por mes
A4: Tipo | B4: Categoría | C4: Descripción | D4: Enero | E4: Febrero | F4: Marzo | G4: Abril | H4: Mayo | I4: Junio | J4: Julio | K4: Agosto | L4: Septiembre | M4: Octubre | N4: Noviembre | O4: Diciembre | P4: TOTAL
A5: SERVICIOS | B5: EXPENSAS | C5: Expensas | D5: 273500 | E5: 218800 | F5: 218800 | G5: 235210 | H5: 246150 | I5: 273500 | J5: 300850 | K5: 300850 | L5: 328200 | P5: =SUM(D5:O5)
A6: SERVICIOS | B6: TV CABLE | C6: Telecentro — CIUDAD | D6: 37984 | E6: 38489 | F6: 39163 | G6: 50000 | H6: 50000 | I6: 48420 | J6: 31999 | K6: 50000 | L6: 69659 | M6: 50000 | N6: 50000 | O6: 50000 | P6: =SUM(D6:O6)
A7: SERVICIOS | B7: GAS | C7: Metrogas — cliente 30010996459 | D7: 26412 | E7: 25745 | F7: 37316 | G7: 37569 | H7: 36014 | I7: 30643 | L7: 105839 | P7: =SUM(D7:O7)
A8: SERVICIOS | B8: LUZ | C8: Luz Edenor — Sanes (cuenta 008917502309) | D8: 127554 | E8: 121952 | F8: 82994 | G8: 56700 | H8: 52012 | I8: 106212 | J8: 128877 | L8: 63980 | P8: =SUM(D8:O8)
A9: SERVICIOS | B9: IMPUESTOS | C9: ABL — partida 397789 | D9: 12435 | H9: 132599 | J9: 26175 | L9: 27635 | P9: =SUM(D9:O9)
A10: SERVICIOS | B10: LIMPIEZA CASA | C10: Limpieza Susana | D10: 650122 | E10: 515550 | F10: 524479 | G10: 501015 | H10: 545533 | I10: 876981 | J10: 400640 | L10: 835200 | P10: =SUM(D10:O10)
A11: SERVICIOS | B11: CASA | C11: AGUS/PSA | P11: =SUM(D11:O11)
A12: SERVICIOS | B12: STREAMING | C12: Streaming música — Spotify | D12: 4640 | E12: 4601 | F12: 4633 | G12: 4503 | H12: 4504 | I12: 4389 | L12: 5999 | P12: =SUM(D12:O12)
A13: SERVICIOS | B13: ALMACEN | C13: ALMACEN SOL | D13: ='Almacen Detalle'!D47 | E13: ='Almacen Detalle'!D87 | F13: ='Almacen Detalle'!D131 | G13: ='Almacen Detalle'!D176 | H13: ='Almacen Detalle'!D228 | I13: ='Almacen Detalle'!D273 | J13: ='Almacen Detalle'!D312 | K13: ='Almacen Detalle'!D354 | L13: ='Almacen Detalle'!D426 | M13: ='Almacen Detalle'!D468 | N13: ='Almacen Detalle'!D510 | O13: ='Almacen Detalle'!D552 | P13: =SUM(D13:O13)
A14: SERVICIOS | B14: ALMACEN | C14: ALMACEN CHRIS | D14: ='Almacen Detalle'!E47 | E14: ='Almacen Detalle'!E87 | F14: ='Almacen Detalle'!E131 | G14: ='Almacen Detalle'!E176 | H14: ='Almacen Detalle'!E228 | I14: ='Almacen Detalle'!E273 | J14: ='Almacen Detalle'!E312 | K14: ='Almacen Detalle'!E354 | L14: ='Almacen Detalle'!E426 | M14: ='Almacen Detalle'!E468 | N14: ='Almacen Detalle'!E510 | O14: ='Almacen Detalle'!E552 | P14: =SUM(D14:O14)
P15: =SUM(D15:O15)
A16: EXTRAS | B16: EXTRAS | C16: Extras Sol | P16: =SUM(D16:O16)
A17: EXTRAS | B17: EXTRAS | C17: Extras Chris | P17: =SUM(D17:O17)
P18: =SUM(D18:O18)
P19: =SUM(D19:O19)
A20: SERVICIOS | B20: SUSCRIPCIONES | C20: PedidosYa Plus | D20: 5490 | E20: 5990
A21: TOTAL | D21: =SUM(D5:D20) | E21: =SUM(E5:E20) | F21: =SUM(F5:F20) | G21: =SUM(G5:G20) | H21: =SUM(H5:H20) | I21: =SUM(I5:I20) | J21: =SUM(J5:J20) | K21: =SUM(K5:K20) | ... O21: =SUM(O5:O20) | P21: =SUM(P5:P19)
A22: CADA UNO | C22: Total ÷ 2 — parte de Sol y de Chris | D22: =D21/2 | E22: =E21/2 | F22: =F21/2 | G22: =G21/2 | H22: =H21/2 | I22: =I21/2 | J22: =J21/2 | K22: =K21/2 | ... O22: =O21/2
A24: SOL | C24: Pendiente Sol = Cada uno − pagado por Sol (todos los servicios + ALMACEN SOL). Positivo: Sol le paga a Chris; negativo: a favor de Sol | D24: =D22-(D21-D14) | E24: =E22-(E21-E14) | F24: =F22-(F21-F14) | G24: =G22-(G21-G14) | H24: =H22-(H21-H14) | I24: =I22-(I21-I14) | J24: =J22-(J21-J14) | K24: =K22-(K21-K14) | ... O24: =O22-(O21-O14)
A25: CHRIS | C25: Pendiente Chris = Cada uno − ALMACEN CHRIS (único pagado por Chris). Positivo: Chris le paga a Sol | D25: =D22-D14 | E25: =E22-E14 | F25: =F22-F14 | G25: =G22-G14 | H25: =H22-H14 | I25: =I22-I14 | J25: =J22-J14 | K25: =K22-K14 | ... O25: =O22-O14
A26: • PedidosYa Plus / suscripciones PedidosYa → CIUDAD SUSCRIPCIONES (no Gasto Personal Sol)
A27: Notas
A28: • Catálogo fijo de conceptos CIUDAD 1132
A29: • Telecentro: $50.000 mensuales hasta nuevo aviso
A30: • Montos enteros, siempre redondeados hacia arriba
A31: • Expensas: abr $235.210 (banco 7-abr → Consorcio De Propiet Patagonia); may/jun desde MP con período Gmail (pago jun=mayo, pago jul=junio). Julio período pendiente.
A32: • En Detalle: Forma de pago, N° Cliente y N° Medidor cuando existan
A33: • ALMACEN SOL / ALMACEN CHRIS: totales automáticos desde hoja "Almacen Detalle"
A34: • TRANSPORTE (Cabify/Uber/Didi/Emova) → solo Gasto Personal Sol; sin fila en matriz 2026
A35: • Dinero retirado: hoja "Dinero Retirado" (no suma al TOTAL de gastos)
A36: • FARMACIA · Farmacity → Almacen Detalle. Farmacia Maure / Selma → Gasto Personal Sol · FARMACIA SALUD
A37: • Personal (Pago directo): va a OHIGGINS → TV CABLE-INTERNET — no CIUDAD
... A49: • TRANSPORTE personal (Cabify/Uber/Didi) → solo hoja "Gasto Personal Sol" (no fila en matriz 2026)

Sheet Cashflow Cuotas BBVA
A1: Compra | B1: Comercio | C1: Categoría | D1: Tarjeta | E1: Cuota | F1: De | G1: Monto cuota | H1: Mes cobro | I1: Año-Mes | J1: Estado | K1: Comentario
A2: 45789 | B2: DIEGOJULIANKOZ | C2: Personal | D2: VISA | E2: 1 | F2: 9 | G2: 84906 | H2: Mayo 2025 | I2: 2025-05 | J2: PAGADO | K2: C.01/09 · cashflow BBVA · gasto personal Sol
A3: 45789 | B3: DIEGOJULIANKOZ | C3: Personal | D3: VISA | E3: 2 | F3: 9 | G3: 84906 | H3: Junio 2025 | I3: 2025-06 | J3: PAGADO | K3: C.02/09 · cashflow BBVA · gasto personal Sol
A4: 45827 | B4: ELCACOSMETICOSINC | C4: Personal | D4: VISA | E4: 1 | F4: 9 | G4: 15054 | H4: Junio 2025 | I4: 2025-06 | J4: PAGADO | K4: C.01/09 · cashflow BBVA · gasto personal Sol
A5: 45815 | B5: MONSERVO | C5: Personal | D5: MASTERCARD | E5: 1 | F5: 9 | G5: 6665 | H5: Junio 2025 | I5: 2025-06 | J5: PAGADO | K5: C.01/09 · cashflow BBVA · gasto personal Sol
A6: 45865 | B6: 3PRODUCTOS | C6: Personal | D6: VISA | E6: 1 | F6: 9 | G6: 5445 | H6: Julio 2025 | I6: 2025-07 | J6: PAGADO | K6: C.01/09 · cashflow BBVA · gasto personal Sol
A7: 45789 | B7: DIEGOJULIANKOZ | C7: Personal | D7: VISA | E7: 3 | F7: 9 | G7: 84906 | H7: Julio 2025 | I7: 2025-07 | J7: PAGADO | K7: C.03/09 · cashflow BBVA · gasto personal Sol
A8: 45827 | B8: ELCACOSMETICOSINC | C8: Personal | D8: VISA | E8: 2 | F8: 9 | G8: 15054 | H8: Julio 2025 | I8: 2025-07 | J8: PAGADO | K8: C.02/09 · cashflow BBVA · gasto personal Sol
A9: 45815 | B9: MONSERVO | C9: Personal | D9: MASTERCARD | E9: 2 | F9: 9 | G9: 6665 | H9: Julio 2025 | I9: 2025-07 | J9: PAGADO | K9: C.02/09 · cashflow BBVA · gasto personal Sol
A10: 45865 | B10: 3PRODUCTOS | C10: Personal | D10: VISA | E10: 2 | F10: 9 | G10: 5445 | H10: Agosto 2025 | I10: 2025-08 | J10: PAGADO | K10: C.02/09 · cashflow BBVA · gasto personal Sol
A11: 45789 | B11: DIEGOJULIANKOZ | C11: Personal | D11: VISA | E11: 4 | F11: 9 | G11: 84906 | H11: Agosto 2025 | I11: 2025-08 | J11: PAGADO | K11: C.04/09 · cashflow BBVA · gasto personal Sol
A12: 45827 | B12: ELCACOSMETICOSINC | C12: Personal | D12: VISA | E12: 3 | F12: 9 | G12: 15054 | H12: Agosto 2025 | I12: 2025-08 | J12: PAGADO | K12: C.03/09 · cashflow BBVA · gasto personal Sol
A13: 45890 | B13: JACKIESMITH | C13: Personal | D13: VISA | E13: 1 | F13: 6 | G13: 10970 | H13: Agosto 2025 | I13: 2025-08 | J13: PAGADO | K13: C.01/06 · cashflow BBVA · gasto personal Sol
... A242: 46151 | B242: ZADIG | C242: ROPA | D242: VISA | E242: 12 | F242: 12 | G242: 69750 | H242: Abril 2027 | I242: 2027-04 | J242: PENDIENTE | K242: C.12/12 · cashflow BBVA · gasto personal Sol
A245: RESUMEN MENSUAL
A246: Año-Mes | B246: PAGADO | C246: PENDIENTE | D246: TOTAL
A247: 2025-05 | B247: 84906 | C247: 0 | D247: 84906
A248: 2025-06 | B248: 106625 | C248: 0 | D248: 106625
A249: 2025-07 | B249: 112070 | C249: 0 | D249: 112070
A250: 2025-08 | B250: 145500 | C250: 0 | D250: 145500
A251: 2025-09 | B251: 459069 | C251: 0 | D251: 459069
A252: 2025-10 | B252: 491695 | C252: 0 | D252: 491695
A253: 2025-11 | B253: 562925 | C253: 0 | D253: 562925
A254: 2025-12 | B254: 579260 | C254: 0 | D254: 579260
A255: 2026-01 | B255: 737143 | C255: 0 | D255: 737143
A256: 2026-02 | B256: 744479 | C256: 0 | D256: 744479
A257: 2026-03 | B257: 649747 | C257: 0 | D257: 649747
A258: 2026-04 | B258: 804100 | C258: 0 | D258: 804100
... A270: 2027-04 | B270: 0 | C270: 130667 | D270: 130667
A271: TOTAL | B271: =SUM(B247:B270) | C271: =SUM(C247:C270) | D271: =SUM(D247:D270)
A274: CASHFLOW PENDIENTE (solo futuro)
A275: Año-Mes | B275: Monto pendiente
A276: 2026-06 | B276: 90283
A277: 2026-07 | B277: 1564269
A278: 2026-08 | B278: 1608575
A279: 2026-09 | B279: 1608575
A280: 2026-10 | B280: 1320624
A281: 2026-11 | B281: 945812
A282: 2026-12 | B282: 945812
A283: 2027-01 | B283: 405667
...

Sheet Almacen Detalle
A1: CIUDAD 1132 — Almacén (detalle día a día)
A2: Totales Sol/Chris alimentan ALMACEN SOL / ALMACEN CHRIS en hoja 2026. Comentario opcional.
A3: Mes | B3: Fecha | C3: Detalle | D3: Importe Sol | E3: Importe Chris | F3: Total | G3: Comentario
A4: Enero | B4: 46053 | C4: Combustible — Shell | D4: 985 | F4: =IF(OR(D4<>"",E4<>""),IF(D4="",0,D4)+IF(E4="",0,E4),"") | G4: MP · Shell
A5: Enero | B5: 46053 | C5: Combustible — Shell | D5: 831 | F5: =IF(OR(D5<>"",E5<>""),IF(D5="",0,D5)+IF(E5="",0,E5),"") | G5: MP · Shell · ex `Combustible — Shell (2)`
A6: Enero | B6: 46035 | C6: COMIDA · pollo | D6: 44846 | F6: =IF(OR(D6<>"",E6<>""),IF(D6="",0,D6)+IF(E6="",0,E6),"") | G6: COMIDA · pollo · BBVA MASTERCARD · neto (bonif 11003)
A7: Enero | B7: 46049 | C7: PEDIDOS YA · SUPERMERCADO · propina | D7: 750 | F7: =IF(OR(D7<>"",E7<>""),IF(D7="",0,D7)+IF(E7="",0,E7),"") | G7: PEDIDOS YA · SUPERMERCADO · propina
A8: Enero | B8: 46049 | C8: PEDIDOS YA · SUPERMERCADO | D8: 35404 | F8: =IF(OR(D8<>"",E8<>""),IF(D8="",0,D8)+IF(E8="",0,E8),"") | G8: PEDIDOS YA · SUPERMERCADO
A9: Marzo | B9: 46090 | C9: ENTRETENIMIENTO · Recitales | D9: 33000 | F9: =IF(OR(D9<>"",E9<>""),IF(D9="",0,D9)+IF(E9="",0,E9),"") | G9: ENTRETENIMIENTO · Recitales · Movistar Arena · Mercado Pago
A10: Marzo | B10: 46090 | C10: ENTRETENIMIENTO · Recitales | D10: 220000 | F10: =IF(OR(D10<>"",E10<>""),IF(D10="",0,D10)+IF(E10="",0,E10),"") | G10: ENTRETENIMIENTO · Recitales · Movistar Arena · Mercado Pago
A11: Mayo | B11: 46168 | C11: ENTRETENIMIENTO · Recitales | D11: 19000 | F11: =IF(OR(D11<>"",E11<>""),IF(D11="",0,D11)+IF(E11="",0,E11),"") | G11: ENTRETENIMIENTO · Recitales · Movistar Arena · Mercado Pago
A12: Febrero | B12: 46078 | C12: ENTRETENIMIENTO · Recitales | D12: 150000 | F12: =IF(OR(D12<>"",E12<>""),IF(D12="",0,D12)+IF(E12="",0,E12),"") | G12: ENTRETENIMIENTO · Recitales · Movistar Arena · BBVA MASTERCARD
A13: Febrero | B13: 46078 | C13: ENTRETENIMIENTO · Recitales | D13: 22500 | F13: =IF(OR(D13<>"",E13<>""),IF(D13="",0,D13)+IF(E13="",0,E13),"") | G13: ENTRETENIMIENTO · Recitales · Movistar Arena · BBVA MASTERCARD
A14: Marzo | B14: 46090 | C14: ENTRETENIMIENTO · Recitales | D14: 22500 | F14: =IF(OR(D14<>"",E14<>""),IF(D14="",0,D14)+IF(E14="",0,E14),"") | G14: ENTRETENIMIENTO · Recitales · Movistar Arena · BBVA MASTERCARD
A15: Enero | B15: 46040 | C15: SUPERMERCADO · Carrefour | D15: 4089 | F15: =IF(OR(D15<>"",E15<>""),IF(D15="",0,D15)+IF(E15="",0,E15),"") | G15: SUPERMERCADO · Carrefour
... A46: Enero | B46: 46050 | C46: RAMON · Veterinario | D46: 145400 | F46: =IF(OR(D46<>"",E46<>""),IF(D46="",0,D46)+IF(E46="",0,E46),"") | G46: RAMON · Veterinario · Valeria Mele / El Perro Verde · ALMACEN SOL
A47: TOTAL ENERO | C47: Totales mes → | D47: =SUMIFS($D$4:$D$800,$A$4:$A$800,"Enero") | E47: =SUMIFS($E$4:$E$800,$A$4:$A$800,"Enero") | F47: =D47+E47
A48: Marzo | B48: 46093 | C48: COMIDA · Barritas proteicas | D48: 66527 | F48: =IF(OR(D48<>"",E48<>""),IF(D48="",0,D48)+IF(E48="",0,E48),"") | G48: COMIDA · Barritas proteicas · Enerfit · TC Mercado Pago · SALUD · MERPAGO*ENERFIT · TC Mercado Pago · cuota 4 de 12 · compra 2025-11-26 · ex `SALUD · Enerfit · C.04/12`
A49: Febrero | B49: 46081 | C49: Combustible — Shell | D49: 61 | F49: =IF(OR(D49<>"",E49<>""),IF(D49="",0,D49)+IF(E49="",0,E49),"") | G49: MP · Shell
A50: Febrero | B50: 46081 | C50: Combustible — Shell | D50: 418 | F50: =IF(OR(D50<>"",E50<>""),IF(D50="",0,D50)+IF(E50="",0,E50),"") | G50: MP · Shell
A51: Febrero | B51: 46081 | C51: Combustible — Shell | D51: 788 | F51: =IF(OR(D51<>"",E51<>""),IF(D51="",0,D51)+IF(E51="",0,E51),"") | G51: MP · Shell
A52: Febrero | B52: 46081 | C52: Combustible — Shell | D52: 605 | F52: =IF(OR(D52<>"",E52<>""),IF(D52="",0,D52)+IF(E52="",0,E52),"") | G52: MP · Shell
A53: Febrero | B53: 46075 | C53: COMIDA · HAVANNA | D53: 9600 | F53: =IF(OR(D53<>"",E53<>""),IF(D53="",0,D53)+IF(E53="",0,E53),"") | G53: COMIDA · HAVANNA
A54: Febrero | B54: 46073 | C54: COMIDA · HAVANNA | D54: 9600 | F54: =IF(OR(D54<>"",E54<>""),IF(D54="",0,D54)+IF(E54="",0,E54),"") | G54: COMIDA · HAVANNA
A55: Febrero | B55: 46071 | C55: SUPERMERCADO · Día | D55: 37335 | F55: =IF(OR(D55<>"",E55<>""),IF(D55="",0,D55)+IF(E55="",0,E55),"") | G55: SUPERMERCADO · Día
A56: Febrero | B56: 46067 | C56: SUPERMERCADO · Día | D56: 5622 | F56: =IF(OR(D56<>"",E56<>""),IF(D56="",0,D56)+IF(E56="",0,E56),"") | G56: SUPERMERCADO · Día
A57: Febrero | B57: 46077 | C57: PEDIDOS YA · SUPERMERCADO · propina | D57: 1000 | F57: =IF(OR(D57<>"",E57<>""),IF(D57="",0,D57)+IF(E57="",0,E57),"") | G57: PEDIDOS YA · SUPERMERCADO · propina · BBVA TC Visa
A58: Febrero | B58: 46065 | C58: REPUESTOS · Sodastream | D58: 53037 | F58: =IF(OR(D58<>"",E58<>""),IF(D58="",0,D58)+IF(E58="",0,E58),"") | G58: REPUESTOS · Sodastream · Mercado Pago · ex CASA/REPUESTOS matriz
A59: Febrero | B59: 46061 | C59: SUPERMERCADO · Carrefour | D59: 21990 | F59: =IF(OR(D59<>"",E59<>""),IF(D59="",0,D59)+IF(E59="",0,E59),"") | G59: SUPERMERCADO · Carrefour
... A82: Febrero | B82: 46078 | C82: PEDIDOS YA · SUPERMERCADO | D82: 2599 | F82: =IF(OR(D82<>"",E82<>""),IF(D82="",0,D82)+IF(E82="",0,E82),"") | G82: PEDIDOS YA · SUPERMERCADO · BBVA TC Visa
A83: Febrero | F83: =IF(OR(D85<>"",E85<>""),IF(D85="",0,D85)+IF(E85="",0,E85),"")
A84: Febrero | B84: 46069 | C84: COMIDA · Soraya | D84: 33100 | F84: =IF(OR(D84<>"",E84<>""),IF(D84="",0,D84)+IF(E84="",0,E84),"") | G84: COMIDA · RESTAURANTSORAYASA · MP cuenta
A85: Febrero | B85: 46076 | C85: RAMON · Veterinario | D85: 72000 | F85: =IF(OR(D85<>"",E85<>""),IF(D85="",0,D85)+IF(E85="",0,E85),"") | G85: RAMON · Veterinario · Valeria Mele / El Perro Verde · ALMACEN SOL
A86: Febrero | B86: 46065 | C86: RAMON · Otros | D86: 27200 | F86: =IF(OR(D86<>"",E86<>""),IF(D86="",0,D86)+IF(E86="",0,E86),"") | G86: RAMON · Otros · Paws Pet Market · Mercado Pago · ALMACEN SOL
A87: TOTAL FEBRERO | C87: Totales mes → | D87: =SUMIFS($D$4:$D$800,$A$4:$A$800,"Febrero") | E87: =SUMIFS($E$4:$E$800,$A$4:$A$800,"Febrero") | F87: =D87+E87
A88: Junio | B88: 46185 | C88: COMIDA · Barritas proteicas | D88: 66527 | F88: =IF(OR(D88<>"",E88<>""),IF(D88="",0,D88)+IF(E88="",0,E88),"") | G88: COMIDA · Barritas proteicas · Enerfit · TC Mercado Pago · SALUD · MERPAGO*ENERFIT · TC Mercado Pago · cuota 7 de 12 · compra 2025-11-26 · ex `SALUD · Enerfit · C.07/12`
A89: Marzo | B89: 46112 | C89: Combustible — Shell | D89: 264 | F89: =IF(OR(D89<>"",E89<>""),IF(D89="",0,D89)+IF(E89="",0,E89),"") | G89: MP · combustible
A90: Marzo | B90: 46112 | C90: Combustible — Shell | D90: 1118 | F90: =IF(OR(D90<>"",E90<>""),IF(D90="",0,D90)+IF(E90="",0,E90),"") | G90: MP · combustible
A91: Marzo | B91: 46112 | C91: Combustible — Shell | D91: 653 | F91: =IF(OR(D91<>"",E91<>""),IF(D91="",0,D91)+IF(E91="",0,E91),"") | G91: MP · combustible
A92: Julio | B92: 46215 | C92: COMIDA · Barritas proteicas | D92: 66527 | F92: =IF(OR(D92<>"",E92<>""),IF(D92="",0,D92)+IF(E92="",0,E92),"") | G92: COMIDA · Barritas proteicas · Enerfit · TC Mercado Pago · SALUD · MERPAGO*ENERFIT · TC Mercado Pago · cuota 8 de 12 · compra 2025-11-26 · ex `SALUD · Enerfit · C.08/12`
...

Sheet Detalle
A1: CIUDAD 1132 — Detalle de gastos 2026
A3: Fecha | B3: Concepto | C3: Descripción | D3: Monto | E3: Forma de pago | F3: N° Cliente | G3: N° Medidor | H3: Notas | I3: Mes
A4: 46023 | B4: LIMPIEZA CASA | C4: LIMPIEZA CASA — Enero 2026 | D4: 650122 | I4: Enero
A5: 46023 | B5: Telecentro | C5: Telecentro CIUDAD — 01/2026 (Gmail) | D5: 37984 | H5: Recurrente $50.000/mes hasta nuevo aviso | I5: Enero
A6: 46029 | B6: Expensas | C6: Expensas — Enero 2026 (pago 1) | D6: 35260 | E6: Transferencia | H6: Consorcio de Propietarios · Pagado | I6: Enero
A7: 46029 | B7: Expensas | C7: Expensas — Enero 2026 (pago 2) | D7: 238240 | E7: Transferencia | H7: Consorcio de Propietarios · Pagado | I7: Enero
A8: 46054 | B8: LIMPIEZA CASA | C8: LIMPIEZA CASA — Febrero 2026 | D8: 515550 | H8: Original: 515.549,50 · redondeado hacia arriba | I8: Febrero
A9: 46054 | B9: Telecentro | C9: Telecentro CIUDAD — 02/2026 (Gmail) | D9: 38489 | H9: Recurrente $50.000/mes hasta nuevo aviso | I9: Febrero
A10: 46041 | B10: Metrogas | C10: Metrogas CIUDAD · cobro 19/01/2026 (fecha de cobro BBVA, no período consumo) | D10: 26412 | E10: Débito automático BBVA Visa | F10: 30010996459 | G10: 40049923
A11: 46059 | B11: Expensas | C11: Expensas — Febrero 2026 | D11: 218800 | E11: Transferencia | H11: Consorcio de Propietarios · Pagado | I11: Febrero
A12: 46082 | B12: LIMPIEZA CASA | C12: LIMPIEZA CASA — Marzo 2026 | D12: 524479 | H12: Original: 524.478,50 · redondeado hacia arriba | I12: Marzo
A13: 46082 | B13: Telecentro | C13: Telecentro CIUDAD — 03/2026 (Gmail) | D13: 39163 | H13: Recurrente $50.000/mes hasta nuevo aviso | I13: Marzo
A14: 46089 | B14: Luz | C14: Edenor — emisión 08/03/2026 · titular Maria Soledad Sanes · CIUDAD · cuenta 008917502309 | D14: 82994 | E14: Débito Visa 3200 | F14: 008917502309 | H14: Vence 16/03/2026 | I14: Marzo
A15: 46071 | B15: Metrogas | C15: Metrogas CIUDAD · cobro 18/02/2026 (fecha de cobro BBVA, no período consumo) | D15: 25745 | E15: Débito automático BBVA Visa | F15: 30010996459 | G15: 40049923
A16: 46091 | B16: Expensas | C16: Expensas — Marzo 2026 | D16: 218800 | E16: Transferencia | H16: Consorcio de Propietarios · Pagado | I16: Marzo
A17: 46119 | B17: Expensas | C17: Expensas — Abril 2026 | D17: 235210 | E17: Transferencia | H17: Consorcio de Propietarios · Pagado · Gmail Sent 7-abr | I17: Abril
A18: 46113 | B18: LIMPIEZA CASA | C18: LIMPIEZA CASA — Abril 2026 | D18: 501015 | I18: Abril
A19: 46113 | B19: Telecentro | C19: Telecentro CIUDAD — servicio mensual 04/2026 | D19: 50000 | H19: Recurrente $50.000/mes hasta nuevo aviso | I19: Abril
A20: 46114 | B20: Luz | C20: Edenor — emisión 02/04/2026 · titular Maria Soledad Sanes · CIUDAD · cuenta 008917502309 | D20: 56700 | E20: Débito Visa 3200 | F20: 008917502309 | H20: Vence 14/04/2026 | I20: Abril
A21: 46132 | B21: Metrogas | C21: Metrogas CIUDAD · cobro 20/04/2026 (fecha de cobro BBVA, no período consumo) | D21: 37569 | E21: Débito automático BBVA Visa | F21: 30010996459 | G21: 40049923
A23: 46143 | B23: LIMPIEZA CASA | C23: LIMPIEZA CASA — Mayo 2026 | D23: 545533 | I23: Mayo
A24: 46143 | B24: Telecentro | C24: Telecentro CIUDAD — servicio mensual 05/2026 | D24: 50000 | H24: Recurrente $50.000/mes hasta nuevo aviso | I24: Mayo
A25: 46144 | B25: Luz | C25: Edenor — emisión 02/05/2026 · titular Maria Soledad Sanes · CIUDAD · cuenta 008917502309 | D25: 52012 | E25: Débito Visa 3200 | F25: 008917502309 | H25: Vence 14/05/2026 | I25: Mayo
A26: 46161 | B26: Metrogas | C26: Metrogas CIUDAD · cobro 19/05/2026 (fecha de cobro BBVA, no período consumo) | D26: 36014 | E26: Débito automático BBVA Visa | F26: 30010996459 | G26: 40049923
A27: 46174 | B27: LIMPIEZA CASA | C27: LIMPIEZA CASA — Junio 2026 | D27: 876981 | H27: Original: 876.980,50 · redondeado hacia arriba | I27: Junio
A28: 46174 | B28: Telecentro | C28: Telecentro CIUDAD — servicio mensual 06/2026 | D28: 50000 | H28: Recurrente $50.000/mes hasta nuevo aviso | I28: Junio
A29: 46176 | B29: Luz | C29: Edenor — emisión 03/06/2026 · titular Maria Soledad Sanes · CIUDAD · cuenta 008917502309 | D29: 106212 | E29: Débito Visa 3200 | F29: 008917502309 | H29: Vence 16/06/2026 | I29: Junio
A30: 46190 | B30: Metrogas | C30: Metrogas CIUDAD · cobro 17/06/2026 (fecha de cobro BBVA, no período consumo) | D30: 30643 | E30: Débito automático BBVA Visa | F30: 30010996459 | G30: 40049923
A31: 46183 | B31: Expensas | C31: Expensas — Mayo 2026 (pago Gmail Sent 10/06) | D31: 246150 | E31: Transferencia | H31: Período mayo · Consorcio De Propietarios · Pagado · Gmail Sent | I31: Mayo
A32: 46204 | B32: Luz | C32: Edenor — emisión 01/07/2026 · titular Maria Soledad Sanes · CIUDAD · cuenta 008917502309 | D32: 128877 | E32: Débito Visa 3200 | F32: 008917502309 | H32: Vence 13/07/2026 | I32: Julio
A33: 46204 | B33: Telecentro | C33: Telecentro CIUDAD — servicio mensual 07/2026 | D33: 50000 | H33: Recurrente $50.000/mes hasta nuevo aviso | I33: Julio
A34: 46212 | B34: Expensas | C34: Expensas — Junio 2026 (pago Gmail Sent 09/07) | D34: 273500 | E34: Transferencia | H34: Período junio · Consorcio De Propietarios · Pagado · Gmail Sent | I34: Junio
A35: 46235 | B35: Telecentro | C35: Telecentro CIUDAD — servicio mensual 08/2026 | D35: 50000 | H35: Recurrente $50.000/mes hasta nuevo aviso | I35: Agosto
A36: 46266 | B36: Telecentro | C36: (duplicado) ver fila débito BBVA 25/09 — no sumar | E36: Débito BBVA | H36: SUPERSEDE · Telecentro Sept está en Detalle débito 25/09 $69.659 | I36: Septiembre
A37: 46296 | B37: Telecentro | C37: Telecentro CIUDAD — servicio mensual 10/2026 | D37: 50000 | H37: Recurrente $50.000/mes hasta nuevo aviso | I37: Octubre
A38: 46327 | B38: Telecentro | C38: Telecentro CIUDAD — servicio mensual 11/2026 | D38: 50000 | H38: Recurrente $50.000/mes hasta nuevo aviso | I38: Noviembre
A39: 46357 | B39: Telecentro | C39: Telecentro CIUDAD — servicio mensual 12/2026 | D39: 50000 | H39: Recurrente $50.000/mes hasta nuevo aviso | I39: Diciembre
A40: 46023 | B40: Streaming | C40: Streaming — prorrateo anual 200.000 / 12 (Enero) | D40: =200000/12 | H40: Total anual 200.000 distribuido en 12 meses | I40: Enero
A41: 46054 | B41: Streaming | C41: Streaming — prorrateo anual 200.000 / 12 (Febrero) | D41: =200000/12 | H41: Total anual 200.000 distribuido en 12 meses | I41: Febrero
A42: 46082 | B42: Streaming | C42: Streaming — prorrateo anual 200.000 / 12 (Marzo) | D42: =200000/12 | H42: Total anual 200.000 distribuido en 12 meses | I42: Marzo
...

Sheet Dinero Retirado
A1: CIUDAD 1132 — Dinero retirado
A2: Retiros de Mercado Pago (concepto «Dinero retirado» / efectivo). No entra en el TOTAL de gastos de la hoja 2026.
A4: Resumen por mes
A5: Mes | B5: Total retirado
A6: Enero | B6: =SUMIF($B$23:$B$500,A6,$D$23:$D$500)
A7: Febrero | B7: =SUMIF($B$23:$B$500,A7,$D$23:$D$500)
A8: Marzo | B8: =SUMIF($B$23:$B$500,A8,$D$23:$D$500)
A9: Abril | B9: =SUMIF($B$23:$B$500,A9,$D$23:$D$500)
A10: Mayo | B10: =SUMIF($B$23:$B$500,A10,$D$23:$D$500)
A11: Junio | B11: =SUMIF($B$23:$B$500,A11,$D$23:$D$500)
A12: Julio | B12: =SUMIF($B$23:$B$500,A12,$D$23:$D$500)
A13: Agosto | B13: =SUMIF($B$23:$B$500,A13,$D$23:$D$500)
A14: Septiembre | B14: =SUMIF($B$23:$B$500,A14,$D$23:$D$500)
A15: Octubre | B15: =SUMIF($B$23:$B$500,A15,$D$23:$D$500)
A16: Noviembre | B16: =SUMIF($B$23:$B$500,A16,$D$23:$D$500)
A17: Diciembre | B17: =SUMIF($B$23:$B$500,A17,$D$23:$D$500)
A18: TOTAL AÑO | B18: =SUM(B6:B17)
A21: Detalle
A22: Fecha | B22: Mes | C22: Concepto | D22: Monto | E22: Medio / destino | F22: Comentario
A23: 46222 | B23: Julio | C23: Susi | D23: 15000 | E23: Mercado Pago · ARS | F23: Dinero retirado · + · financió transferencia Matias Aranda
A24: 46221 | B24: Julio | C24: Palermo | D24: 593000 | E24: Mercado Pago · ARS | F24: Dinero retirado · + · financió transferencia Analia Roay
A25: 46221 | B25: Julio | C25: Gastos | D25: 845 | E25: Mercado Pago · USD | F25: Dinero retirado · + US$844.37 → ceil 845
A26: 46221 | B26: Julio | C26: Susi | D26: 120000 | E26: Mercado Pago · ARS | F26: Dinero retirado · +
A27: 46221 | B27: Julio | C27: AVA | D27: 36813 | E27: Mercado Pago · ARS | F27: Dinero retirado · + · ceil 36812.97
A28: 46221 | B28: Julio | C28: Susi | D28: 1 | E28: Mercado Pago · ARS | F28: Dinero retirado · +
A29: 46221 | B29: Julio | C29: Susi | D29: 147660 | E29: Mercado Pago · ARS | F29: Dinero retirado · + · pareado pago deuda / Susana
A30: 46221 | B30: Julio | C30: Susi | D30: 60000 | E30: Mercado Pago · ARS | F30: Dinero retirado · + · pareado pago deuda 60k
A31: 46220 | B31: Julio | C31: Susi | D31: 30000 | E31: Mercado Pago · ARS | F31: Dinero retirado · +
A32: 46218 | B32: Julio | C32: Gastos | D32: 500 | E32: Mercado Pago · USD | F32: Dinero retirado · + US$500 · pareado Sanes propia
A33: 46266 | B33: Septiembre | C33: AVA | D33: 1000000 | E33: Mercado Pago · ARS | F33: Dinero retirado · + · op 176670344236 · resumen oficial cuenta MP 1–30 sep 2026
A34: 46266 | B34: Septiembre | C34: Expensas | D34: 100000 | E34: Mercado Pago · ARS | F34: Dinero retirado · + · op 176670197960 · resumen oficial cuenta MP 1–30 sep 2026
... A49: 46290 | B49: Septiembre | C49: Tarjeta MELI | D49: 1811722 | E49: Mercado Pago · ARS | F49: Dinero retirado · + · op 179934162641 · resumen oficial cuenta MP 1–30 sep 2026

Sheet MP No Gasto
A1: CIUDAD 1132 — MP No Gasto (nunca ALMACÉN / nunca matriz 2026)
A2: Dinero retirado · Reserva automática / Dinero reservado · Pago de resumen TC · Pago de deuda MP · Inversión (venta/compra USD, bonos, PF). NUNCA van a Almacen Detalle ni suman gastos.
A4: Resumen por tipo (julio+)
A5: Tipo | B5: Cantidad | C5: Suma montos (ARS abs)
A6: Dinero retirado | B6: =COUNTIF($C$24:$C$500,A6) | C6: =SUMIF($C$24:$C$500,A6,$E$24:$E$500)
A7: Reserva automática | B7: =COUNTIF($C$24:$C$500,A7) | C7: =SUMIF($C$24:$C$500,A7,$E$24:$E$500)
A8: Dinero reservado | B8: =COUNTIF($C$24:$C$500,A8) | C8: =SUMIF($C$24:$C$500,A8,$E$24:$E$500)
A9: Pago de deuda MP | B9: =COUNTIF($C$24:$C$500,A9) | C9: =SUMIF($C$24:$C$500,A9,$E$24:$E$500)
A10: Pago de resumen TC | B10: =COUNTIF($C$24:$C$500,A10) | C10: =SUMIF($C$24:$C$500,A10,$E$24:$E$500)
A11: Inversión | B11: =COUNTIF($C$24:$C$500,A11) | C11: =SUMIF($C$24:$C$500,A11,$E$24:$E$500)
A13: TOTAL REGISTROS | B13: =SUM(B6:B11) | C13: =SUM(C6:C11)
A15: Norma
A16: Al analizar extractos MP: si el concepto es Dinero retirado, Reserva automática, Dinero reservado, Pago de resumen / Pago de deuda MP, o Inversión (venta/compra de dólares, bonos, plazos fijos, fondos) → registrar SOLO en esta hoja (y espejo en Dinero Retirado / Inversión / Pago de Tarjetas si aplica). NUNCA en Almacen Detalle, NUNCA como gasto de la hoja 2026.
A21: Detalle
A23: Fecha | B23: Mes | C23: Tipo | D23: Concepto | E23: Monto | F23: Moneda | G23: Medio | H23: Comentario
A24: 46222 | B24: Julio | C24: Dinero retirado | D24: Susi | E24: 15000 | F24: ARS | G24: Mercado Pago | H24: Dinero retirado · + · financió transferencia Matias Aranda
A25: 46221 | B25: Julio | C25: Dinero retirado | D25: Palermo | E25: 593000 | F25: ARS | G25: Mercado Pago | H25: Dinero retirado · + · financió transferencia Analia Roay
A26: 46221 | B26: Julio | C26: Inversión | D26: Venta de dólares | E26: 1261633 | F26: ARS | G26: Mercado Pago | H26: Venta de dólares · + · en proceso · ceil 1261632.32
A27: 46221 | B27: Julio | C27: Dinero retirado | D27: Gastos | E27: 845 | F27: USD | G27: Mercado Pago | H27: Dinero retirado · + US$844.37 → ceil 845
A28: 46221 | B28: Julio | C28: Dinero reservado | D28: Susi | E28: 5654 | F28: ARS | G28: Mercado Pago | H28: Dinero reservado · − · ceil 5653.97 · NUNCA almacén
A29: 46221 | B29: Julio | C29: Reserva automática | D29: AVA | E29: 500 | F29: ARS | G29: Mercado Pago | H29: Reserva automática · − · NUNCA almacén
A30: 46221 | B30: Julio | C30: Reserva automática | D30: Susi | E30: 3000 | F30: ARS | G30: Mercado Pago | H30: Reserva automática · − · NUNCA almacén
A31: 46221 | B31: Julio | C31: Dinero retirado | D31: Susi | E31: 120000 | F31: ARS | G31: Mercado Pago | H31: Dinero retirado · +
A32: 46221 | B32: Julio | C32: Dinero retirado | D32: AVA | E32: 36813 | F32: ARS | G32: Mercado Pago | H32: Dinero retirado · + · ceil 36812.97
A33: 46221 | B33: Julio | C33: Dinero retirado | D33: Susi | E33: 1 | F33: ARS | G33: Mercado Pago | H33: Dinero retirado · +
A34: 46221 | B34: Julio | C34: Pago de deuda MP | D34: Mercado Pago | E34: 147660 | F34: ARS | G34: Mercado Pago | H34: Pago de deuda · − · pareado con retiro Susi 147660 · NUNCA almacén
A35: 46221 | B35: Julio | C35: Dinero retirado | D35: Susi | E35: 147660 | F35: ARS | G35: Mercado Pago | H35: Dinero retirado · + · pareado pago deuda / Susana
... A51: 46220 | B51: Julio | C51: Reserva automática | D51: AVA | E51: 500 | F51: ARS | G51: Mercado Pago | H51: Reserva automática · − · 17:15 · NUNCA almacén
A52: 46253 | B52: Agosto | C52: Pago de resumen TC | D52: Tarjeta de crédito Mercado Pago | E52: 1200000 | F52: ARS | G52: Mercado Pago
A53: 46253 | B53: Agosto | C53: Pago de resumen TC | D53: Tarjeta de crédito Mercado Pago | E53: 1225483 | F53: ARS | G53: Mercado Pago
A54: 46266 | B54: Septiembre | C54: Dinero reservado | D54: Susi | E54: 500000 | F54: ARS | G54: Mercado Pago | H54: Dinero reservado · − · op 175715708841 · NUNCA almacén · resumen oficial cuenta MP 1–30 sep 2026
A55: 46266 | B55: Septiembre | C55: Dinero reservado | D55: AVA | E55: 4300000 | F55: ARS | G55: Mercado Pago | H55: Dinero reservado · − · op 176669207270 · NUNCA almacén · resumen oficial cuenta MP 1–30 sep 2026
A56: 46266 | B56: Septiembre | C56: Dinero retirado | D56: AVA | E56: 1000000 | F56: ARS | G56: Mercado Pago | H56: Dinero retirado · + · op 176670344236 · resumen oficial cuenta MP 1–30 sep 2026
A57: 46266 | B57: Septiembre | C57: Dinero reservado | D57: Expensas | E57: 1000000 | F57: ARS | G57: Mercado Pago | H57: Dinero reservado · − · op 176669891822 · NUNCA almacén · resumen oficial cuenta MP 1–30 sep 2026
A58: 46266 | B58: Septiembre | C58: Dinero retirado | D58: Expensas | E58: 100000 | F58: ARS | G58: Mercado Pago | H58: Dinero retirado · + · op 176670197960 · resumen oficial cuenta MP 1–30 sep 2026
A59: 46266 | B59: Septiembre | C59: Reserva automática | D59: Susi | E59: 3000 | F59: ARS | G59: Mercado Pago | H59: Reserva automática · − · op 175716957483 · NUNCA almacén · resumen oficial cuenta MP 1–30 sep 2026
A60: 46266 | B60: Septiembre | C60: Reserva automática | D60: AVA | E60: 500 | F60: ARS | G60: Mercado Pago | H60: Reserva automática · − · op 176670874948 · NUNCA almacén · resumen oficial cuenta MP 1–30 sep 2026
A61: 46266 | B61: Septiembre | C61: Inversión | D61: Venta de dólares | E61: 1715612 | F61: ARS | G61: Mercado Pago | H61: Inversión · Rescate · + · op 175716248657 · ceil 1715611.4 · resumen oficial cuenta MP 1–30 sep 2026
A62: 46266 | B62: Septiembre | C62: Dinero reservado | D62: Tarjeta MELI | E62: 1799162 | F62: ARS | G62: Mercado Pago | H62: Dinero reservado · − · op 176697071778 · NUNCA almacén · resumen oficial cuenta MP 1–30 sep 2026
A63: 46266 | B63: Septiembre | C63: Dinero retirado | D63: Tarjeta MELI | E63: 45000 | F63: ARS | G63: Mercado Pago | H63: Dinero retirado · + · op 176771280062 · resumen oficial cuenta MP 1–30 sep 2026
...

Sheet Inversión
A1: CIUDAD 1132 — Inversión
A2: Bonos, plazos fijos, fondos y otros movimientos de inversión. No suma al TOTAL de gastos de la hoja 2026.
A4: Resumen por mes
A5: Mes | B5: Invertido | C5: Rescatado | D5: Rendimiento | E5: Neto
A6: Enero | B6: =SUMIFS($F$24:$F$500,$B$24:$B$500,A6,$D$24:$D$500,"Inversión") | C6: =SUMIFS($F$24:$F$500,$B$24:$B$500,A6,$D$24:$D$500,"Rescate") | D6: =SUMIFS($F$24:$F$500,$B$24:$B$500,A6,$D$24:$D$500,"Rendimiento") | E6: =C6+D6-B6
A7: Febrero | B7: =SUMIFS($F$24:$F$500,$B$24:$B$500,A7,$D$24:$D$500,"Inversión") | C7: =SUMIFS($F$24:$F$500,$B$24:$B$500,A7,$D$24:$D$500,"Rescate") | D7: =SUMIFS($F$24:$F$500,$B$24:$B$500,A7,$D$24:$D$500,"Rendimiento") | E7: =C7+D7-B7
A8: Marzo | B8: =SUMIFS($F$24:$F$500,$B$24:$B$500,A8,$D$24:$D$500,"Inversión") | C8: =SUMIFS($F$24:$F$500,$B$24:$B$500,A8,$D$24:$D$500,"Rescate") | D8: =SUMIFS($F$24:$F$500,$B$24:$B$500,A8,$D$24:$D$500,"Rendimiento") | E8: =C8+D8-B8
A9: Abril | B9: =SUMIFS($F$24:$F$500,$B$24:$B$500,A9,$D$24:$D$500,"Inversión") | C9: =SUMIFS($F$24:$F$500,$B$24:$B$500,A9,$D$24:$D$500,"Rescate") | D9: =SUMIFS($F$24:$F$500,$B$24:$B$500,A9,$D$24:$D$500,"Rendimiento") | E9: =C9+D9-B9
A10: Mayo | B10: =SUMIFS($F$24:$F$500,$B$24:$B$500,A10,$D$24:$D$500,"Inversión") | C10: =SUMIFS($F$24:$F$500,$B$24:$B$500,A10,$D$24:$D$500,"Rescate") | D10: =SUMIFS($F$24:$F$500,$B$24:$B$500,A10,$D$24:$D$500,"Rendimiento") | E10: =C10+D10-B10
A11: Junio | B11: =SUMIFS($F$24:$F$500,$B$24:$B$500,A11,$D$24:$D$500,"Inversión") | C11: =SUMIFS($F$24:$F$500,$B$24:$B$500,A11,$D$24:$D$500,"Rescate") | D11: =SUMIFS($F$24:$F$500,$B$24:$B$500,A11,$D$24:$D$500,"Rendimiento") | E11: =C11+D11-B11
A12: Julio | B12: =SUMIFS($F$24:$F$500,$B$24:$B$500,A12,$D$24:$D$500,"Inversión") | C12: =SUMIFS($F$24:$F$500,$B$24:$B$500,A12,$D$24:$D$500,"Rescate") | D12: =SUMIFS($F$24:$F$500,$B$24:$B$500,A12,$D$24:$D$500,"Rendimiento") | E12: =C12+D12-B12
A13: Agosto | B13: =SUMIFS($F$24:$F$500,$B$24:$B$500,A13,$D$24:$D$500,"Inversión") | C13: =SUMIFS($F$24:$F$500,$B$24:$B$500,A13,$D$24:$D$500,"Rescate") | D13: =SUMIFS($F$24:$F$500,$B$24:$B$500,A13,$D$24:$D$500,"Rendimiento") | E13: =C13+D13-B13
A14: Septiembre | B14: =SUMIFS($F$24:$F$500,$B$24:$B$500,A14,$D$24:$D$500,"Inversión") | C14: =SUMIFS($F$24:$F$500,$B$24:$B$500,A14,$D$24:$D$500,"Rescate") | D14: =SUMIFS($F$24:$F$500,$B$24:$B$500,A14,$D$24:$D$500,"Rendimiento") | E14: =C14+D14-B14
A15: Octubre | B15: =SUMIFS($F$24:$F$500,$B$24:$B$500,A15,$D$24:$D$500,"Inversión") | C15: =SUMIFS($F$24:$F$500,$B$24:$B$500,A15,$D$24:$D$500,"Rescate") | D15: =SUMIFS($F$24:$F$500,$B$24:$B$500,A15,$D$24:$D$500,"Rendimiento") | E15: =C15+D15-B15
A16: Noviembre | B16: =SUMIFS($F$24:$F$500,$B$24:$B$500,A16,$D$24:$D$500,"Inversión") | C16: =SUMIFS($F$24:$F$500,$B$24:$B$500,A16,$D$24:$D$500,"Rescate") | D16: =SUMIFS($F$24:$F$500,$B$24:$B$500,A16,$D$24:$D$500,"Rendimiento") | E16: =C16+D16-B16
A17: Diciembre | B17: =SUMIFS($F$24:$F$500,$B$24:$B$500,A17,$D$24:$D$500,"Inversión") | C17: =SUMIFS($F$24:$F$500,$B$24:$B$500,A17,$D$24:$D$500,"Rescate") | D17: =SUMIFS($F$24:$F$500,$B$24:$B$500,A17,$D$24:$D$500,"Rendimiento") | E17: =C17+D17-B17
A18: TOTAL AÑO | B18: =SUM(B6:B17) | C18: =SUM(C6:C17) | D18: =SUM(D6:D17) | E18: =SUM(E6:E17)
A21: Detalle
A23: Fecha | B23: Mes | C23: Tipo | D23: Movimiento | E23: Instrumento / concepto | F23: Monto | G23: Entidad / medio | H23: Vencimiento | I23: Tasa / rendimiento | J23: Comentario
A24: 46221 | B24: Julio | C24: USD | D24: Rescate | E24: Venta de dólares | F24: 1261633 | G24: Mercado Pago | J24: En proceso · ceil 1.261.632,32 · también en MP No Gasto
A25: 46218 | B25: Julio | C25: Bonos/PF | D25: Inversión | E25: Bonos, plazos fijos y más | F25: 1000000 | G25: Mercado Pago
A26: 46266 | B26: Septiembre | C26: USD | D26: Rescate | E26: Venta de dólares | F26: 1715612 | G26: Mercado Pago | J26: Rescate · op 175716248657 · resumen oficial cuenta MP 1–30 sep 2026
A27: 46275 | B27: Septiembre | C27: USD | D27: Rescate | E27: Venta de dólares | F27: 2989714 | G27: Mercado Pago | J27: Rescate · op 178296615510 · resumen oficial cuenta MP 1–30 sep 2026
A28: 46276 | B28: Septiembre | C28: Bonos/PF | D28: Rescate | E28: Bonos, plazos fijos y más | F28: 12361244 | G28: Mercado Pago | J28: Rescate · op 178259630038 · resumen oficial cuenta MP 1–30 sep 2026
A29: 46280 | B29: Septiembre | C29: USD | D29: Rescate | E29: Venta de dólares | F29: 59334 | G29: Mercado Pago | J29: Rescate · op 178124944219 · resumen oficial cuenta MP 1–30 sep 2026

Sheet Transferencias recibidas
A1: CIUDAD 1132 — Transferencias recibidas
A2: Movimientos Mercado Pago «Transferencia recibida». No entra en el total de gastos de la hoja 2026.
A4: Resumen por mes
A5: Mes | B5: Total recibido
A6: Enero | B6: =SUMIF($B$23:$B$500,A6,$D$23:$D$500)
A7: Febrero | B7: =SUMIF($B$23:$B$500,A7,$D$23:$D$500)
A8: Marzo | B8: =SUMIF($B$23:$B$500,A8,$D$23:$D$500)
A9: Abril | B9: =SUMIF($B$23:$B$500,A9,$D$23:$D$500)
A10: Mayo | B10: =SUMIF($B$23:$B$500,A10,$D$23:$D$500)
A11: Junio | B11: =SUMIF($B$23:$B$500,A11,$D$23:$D$500)
A12: Julio | B12: =SUMIF($B$23:$B$500,A12,$D$23:$D$500)
A13: Agosto | B13: =SUMIF($B$23:$B$500,A13,$D$23:$D$500)
A14: Septiembre | B14: =SUMIF($B$23:$B$500,A14,$D$23:$D$500)
A15: Octubre | B15: =SUMIF($B$23:$B$500,A15,$D$23:$D$500)
A16: Noviembre | B16: =SUMIF($B$23:$B$500,A16,$D$23:$D$500)
A17: Diciembre | B17: =SUMIF($B$23:$B$500,A17,$D$23:$D$500)
A18: TOTAL AÑO | B18: =SUM(B6:B17)
A21: Detalle
A22: Fecha | B22: Mes | C22: Origen / concepto | D22: Monto | E22: Medio | F22: Comentario
A23: 46030 | B23: Enero | C23: Maria Martinez | D23: 46300 | E23: Mercado Pago — Transferencia recibida | F23: settlement · ingreso recibido
A24: 46030 | B24: Enero | C24: Florencia Ivana Risi | D24: 46300 | E24: Mercado Pago — Transferencia recibida | F24: settlement · ingreso recibido
A25: 46030 | B25: Enero | C25: GR | D25: 46300 | E25: Mercado Pago — Transferencia recibida | F25: settlement · ingreso recibido
A26: 46031 | B26: Enero | C26: Antonela | D26: 46300 | E26: Mercado Pago — Transferencia recibida | F26: settlement · ingreso recibido
A27: 46031 | B27: Enero | C27: Lujan Paz | D27: 46300 | E27: Mercado Pago — Transferencia recibida | F27: settlement · ingreso recibido
A28: 46108 | B28: Marzo | C28: Trade in mla Prod | D28: 408100 | E28: Mercado Pago — Transferencia recibida | F28: settlement · ingreso recibido
A29: 46130 | B29: Abril | C29: Lujan Paz | D29: 39000 | E29: Mercado Pago — Transferencia recibida | F29: settlement · ingreso recibido
A30: 46130 | B30: Abril | C30: Ana | D30: 39000 | E30: Mercado Pago — Transferencia recibida | F30: settlement · ingreso recibido
A31: 46130 | B31: Abril | C31: Antonela | D31: 39000 | E31: Mercado Pago — Transferencia recibida | F31: settlement · ingreso recibido
A32: 46130 | B32: Abril | C32: Maria Martinez | D32: 39000 | E32: Mercado Pago — Transferencia recibida | F32: settlement · ingreso recibido
A33: 46140 | B33: Abril | C33: Maria Florencia Colombo | D33: 34000 | E33: Mercado Pago — Transferencia recibida | F33: settlement · ingreso recibido
A34: 46140 | B34: Abril | C34: Maria Martinez | D34: 34900 | E34: Mercado Pago — Transferencia recibida | F34: settlement · ingreso recibido
... A50: 46280 | B50: Septiembre | C50: MarIa Sanes | D50: 1490352 | E50: Mercado Pago — Transferencia recibida | F50: recibida · op 179102139324 · resumen oficial cuenta MP 1–30 sep 2026

Sheet Pago de Tarjetas
A1: CIUDAD 1132 — Pago de tarjetas
A2: Pagos de resumen de tarjeta de crédito (no es gasto nuevo de la hoja 2026; registro de egreso MP).
A4: Resumen por mes
A5: Mes | B5: Total
A6: Enero | B6: =SUMIF($B$23:$B$200,A6,$D$23:$D$200)
A7: Febrero | B7: =SUMIF($B$23:$B$200,A7,$D$23:$D$200)
A8: Marzo | B8: =SUMIF($B$23:$B$200,A8,$D$23:$D$200)
A9: Abril | B9: =SUMIF($B$23:$B$200,A9,$D$23:$D$200)
A10: Mayo | B10: =SUMIF($B$23:$B$200,A10,$D$23:$D$200)
A11: Junio | B11: =SUMIF($B$23:$B$200,A11,$D$23:$D$200)
A12: Julio | B12: =SUMIF($B$23:$B$200,A12,$D$23:$D$200)
A13: Agosto | B13: =SUMIF($B$23:$B$200,A13,$D$23:$D$200)
A14: Septiembre | B14: =SUMIF($B$23:$B$200,A14,$D$23:$D$200)
A15: Octubre | B15: =SUMIF($B$23:$B$200,A15,$D$23:$D$200)
A16: Noviembre | B16: =SUMIF($B$23:$B$200,A16,$D$23:$D$200)
A17: Diciembre | B17: =SUMIF($B$23:$B$200,A17,$D$23:$D$200)
A18: TOTAL AÑO | B18: =SUM(B6:B17)
A21: Detalle
A22: Fecha | B22: Mes | C22: Concepto | D22: Monto | E22: Medio | F22: Comentario
A23: 46031 | B23: Enero | C23: Tarjeta de crédito | D23: 164709 | E23: Mercado Pago | F23: pago resumen TC · hoja Pago de Tarjetas
A24: 46034 | B24: Enero | C24: Tarjeta de crédito | D24: 200000 | E24: Mercado Pago | F24: pago resumen TC · hoja Pago de Tarjetas
A25: 46035 | B25: Enero | C25: Tarjeta de crédito | D25: 1282375 | E25: Mercado Pago | F25: pago resumen TC · hoja Pago de Tarjetas
A26: 46190 | B26: Junio | C26: Tarjeta de crédito | D26: 1501833 | E26: Mercado Pago | F26: pago resumen · hoja Pago de Tarjetas
A27: 46218 | B27: Julio | C27: Tarjeta de crédito | D27: 576242 | E27: Mercado Pago | F27: Pago de resumen · ceil 576241.18 · hoja Pago de Tarjetas / MP No Gasto
A28: 46253 | B28: Agosto | C28: Tarjeta de crédito | D28: 1200000 | E28: Mercado Pago | F28: Pago de resumen · $1.200.000 · composición resumen TC MP sep
A29: 46253 | B29: Agosto | C29: Tarjeta de crédito | D29: 1225483 | E29: Mercado Pago | F29: Pago de resumen · $1.225.482,78 ceil · composición resumen TC MP sep
A30: 46295 | B30: Septiembre | C30: Tarjeta de crédito | D30: 500000 | E30: Mercado Pago | F30: Pago de resumen · $500.000 · op 181614816434 · resumen oficial cuenta MP 1–30 sep 2026

Sheet Expensas Consorcios
A1: CIUDAD 1132 — Expensas Consorcios (Pago de Expensas)
A2: Transferencias a consorcios. CIUDAD = Consorcio De Propietarios o destino Banco Patagonia CBU 0340116900116010765007 / CUIL 30714962473. No va a ALMACEN SOL.
A4: Resumen por propiedad | D4: ID bancario CIUDAD
A5: Propiedad | B5: Total | D5: Entidad | E5: Banco Patagonia
A6: CIUDAD 1132 | B6: =SUMIF($D$29:$D$200,A6,$E$29:$E$200) | D6: CBU | E6: 0340116900116010765007
A7: BONORINO | B7: =SUMIF($D$29:$D$200,A7,$E$29:$E$200) | D7: CUIL | E7: 30714962473
A8: AVA | B8: =SUMIF($D$29:$D$200,A8,$E$29:$E$200)
A9: OHIGGINS (ex A CONFIRMAR / Copropi) | B9: =SUMIF($D$29:$D$200,A9,$E$29:$E$200)
A10: Resumen por mes
A11: Mes | B11: Total
A12: Enero | B12: =SUMIF($B$29:$B$200,A12,$E$29:$E$200)
A13: Febrero | B13: =SUMIF($B$29:$B$200,A13,$E$29:$E$200)
A14: Marzo | B14: =SUMIF($B$29:$B$200,A14,$E$29:$E$200)
A15: Abril | B15: =SUMIF($B$29:$B$200,A15,$E$29:$E$200)
A16: Mayo | B16: =SUMIF($B$29:$B$200,A16,$E$29:$E$200)
A17: Junio | B17: =SUMIF($B$29:$B$200,A17,$E$29:$E$200)
A18: Julio | B18: =SUMIF($B$29:$B$200,A18,$E$29:$E$200)
A19: Agosto | B19: =SUMIF($B$29:$B$200,A19,$E$29:$E$200)
A20: Septiembre | B20: =SUMIF($B$29:$B$200,A20,$E$29:$E$200)
A21: Octubre | B21: =SUMIF($B$29:$B$200,A21,$E$29:$E$200)
A22: Noviembre | B22: =SUMIF($B$29:$B$200,A22,$E$29:$E$200)
A23: Diciembre | B23: =SUMIF($B$29:$B$200,A23,$E$29:$E$200)
A24: TOTAL AÑO | B24: =SUM(B12:B23)
A27: Detalle
A28: Fecha | B28: Mes | C28: Consorcio | D28: Propiedad | E28: Monto | F28: Medio | G28: Comentario
A29: 46029 | B29: Enero | C29: Consorcio De Propiet | D29: CIUDAD 1132 | E29: 35260 | F29: Mercado Pago — Transferencia enviada | G29: Pago de Expensas · CIUDAD 1132 · Patagonia CBU 0340116900116010765007 / CUIL 30714962473
A30: 46029 | B30: Enero | C30: Consorcio De Propiet | D30: CIUDAD 1132 | E30: 238240 | F30: Mercado Pago — Transferencia enviada | G30: Pago de Expensas · CIUDAD 1132 · Patagonia CBU 0340116900116010765007 / CUIL 30714962473
A31: 46031 | B31: Enero | C31: Consorcio De Copropi | D31: OHIGGINS | E31: 376564 | F31: Mercado Pago — Transferencia enviada | G31: Pago de Expensas · OHIGGINS 2219 piso 8 · Estudio Kalmus
A32: 46059 | B32: Febrero | C32: Consorcio De Copropi | D32: OHIGGINS | E32: 395551 | F32: Mercado Pago — Transferencia enviada | G32: Pago de Expensas · OHIGGINS 2219 piso 8 · Estudio Kalmus
A33: 46059 | B33: Febrero | C33: Consorcio De Propiet | D33: CIUDAD 1132 | E33: 218800 | F33: Mercado Pago — Transferencia enviada | G33: Pago de Expensas · CIUDAD 1132 · Patagonia CBU 0340116900116010765007 / CUIL 30714962473
A34: 46091 | B34: Marzo | C34: Consorcio De Copropi | D34: OHIGGINS | E34: 402934 | F34: Mercado Pago — Transferencia enviada | G34: Pago de Expensas · OHIGGINS 2219 piso 8 · Estudio Kalmus
A35: 46091 | B35: Marzo | C35: Consorcio De Propiet | D35: CIUDAD 1132 | E35: 218800 | F35: Mercado Pago — Transferencia enviada | G35: Pago de Expensas · CIUDAD 1132 · Patagonia CBU 0340116900116010765007 / CUIL 30714962473
A36: 46154 | B36: Mayo | C36: Cons De Prop E Bonorino 82 | D36: BONORINO | E36: 200340 | F36: Mercado Pago — Transferencia enviada | G36: Pago de Expensas · BONORINO
A37: 46183 | B37: Junio | C37: Cons De Prop E Bonorino 82 | D37: BONORINO | E37: 219145 | F37: Mercado Pago — Transferencia enviada | G37: Pago de Expensas · BONORINO
A38: 46183 | B38: Mayo | C38: Consorcio De Copropi | D38: OHIGGINS | E38: 666347 | F38: Mercado Pago — Transferencia enviada | G38: Pago de Expensas · OHIGGINS 2219 piso 8 · Estudio Kalmus
A39: 46183 | B39: Mayo | C39: Consorcio De Propiet | D39: CIUDAD 1132 | E39: 246150 | F39: Mercado Pago — Transferencia enviada | G39: Pago de Expensas · CIUDAD 1132 · Patagonia CBU 0340116900116010765007 / CUIL 30714962473 · período mayo 2026 (Gmail Sent)
A40: 46212 | B40: Julio | C40: Cons De Prop E Bonorino 82 | D40: BONORINO | E40: 209393 | F40: Mercado Pago — Transferencia enviada | G40: Pago de Expensas · BONORINO
... A48: 46244 | B48: Julio | C48: Consorcio De Propiet | D48: CIUDAD 1132 | E48: 300850 | F48: Mercado Pago — Transferencia enviada | G48: Pago de Expensas · CIUDAD 1132 · Patagonia CBU 0340116900116010765007 / CUIL 30714962473 · período julio 2026 (Gmail Sent 10/08 · op 173005218278)

Sheet Gasto Personal Sol
A1: CIUDAD 1132 — Gasto personal Sol
A2: Gastos personales de Sol. Incluye cuotas BBVA proyectadas (PROYECTADO). Ver hoja "Cashflow Cuotas BBVA". NO es ALMACEN SOL. No suma al total de la hoja 2026. Incluye PERCEPCIÓN USD (RG 5617 / IVA RG 4240 / IIBB CABA) de resúmenes BBVA. Incluye consumos y PERCEPCIÓN USD de Tarjeta de crédito Mercado Pago (RESUMEN TC MP).
A4: Resumen por mes
A5: Mes | B5: Total
A6: Enero | B6: =SUMIF($B$26:$B$5000,A6,$D$26:$D$5000)
A7: Febrero | B7: =SUMIF($B$26:$B$5000,A7,$D$26:$D$5000)
A8: Marzo | B8: =SUMIF($B$26:$B$5000,A8,$D$26:$D$5000)
A9: Abril | B9: =SUMIF($B$26:$B$5000,A9,$D$26:$D$5000)
A10: Mayo | B10: =SUMIF($B$26:$B$5000,A10,$D$26:$D$5000)
A11: Junio | B11: =SUMIF($B$26:$B$5000,A11,$D$26:$D$5000)
A12: Julio | B12: =SUMIF($B$26:$B$5000,A12,$D$26:$D$5000)
A13: Agosto | B13: =SUMIF($B$26:$B$5000,A13,$D$26:$D$5000)
A14: Septiembre | B14: =SUMIF($B$26:$B$5000,A14,$D$26:$D$5000)
A15: Octubre | B15: =SUMIF($B$26:$B$5000,A15,$D$26:$D$5000)
A16: Noviembre | B16: =SUMIF($B$26:$B$5000,A16,$D$26:$D$5000)
A17: Diciembre | B17: =SUMIF($B$26:$B$5000,A17,$D$26:$D$5000)
A18: TOTAL AÑO | B18: =SUM(B6:B17)
A19: Resumen cuotas proyectadas 2027+ (Mes con año en detalle)
A20: Enero 2027 | B20: =SUMIF($B$26:$B$5000,A20,$D$26:$D$5000)
A21: Febrero 2027 | B21: =SUMIF($B$26:$B$5000,A21,$D$26:$D$5000)
A22: Marzo 2027 | B22: =SUMIF($B$26:$B$5000,A22,$D$26:$D$5000)
A23: Abril 2027 | B23: =SUMIF($B$26:$B$5000,A23,$D$26:$D$5000)
A24: TOTAL PROYECTADO 2027+ | B24: =SUM(B20:B23)
A25: Fecha | B25: Mes | C25: Concepto | D25: Monto | E25: Medio | F25: Comentario
A26: 46024 | B26: Enero | C26: MERCADO LIBRE | D26: 50523 | E26: Mercado Pago | F26: MERCADO LIBRE · gasto personal Sol
A27: 46026 | B27: Enero | C27: VESTIMENTA | D27: 530000 | E27: Mercado Pago | F27: ROPA · Ceferina · hoja Gasto Personal Sol
A28: 46026 | B28: Enero | C28: TRANSFERENCIAS | D28: 4850 | E28: Mercado Pago | F28: tienda física · gasto personal Sol (ex-PENDIENTE) · ex `Gusmar Hnos Srl`
A29: 46026 | B29: Enero | C29: COMPRAS | D29: 382500 | E29: Mercado Pago | F29: COMPRAS · Tiempo Latino · compra TC · gasto personal Sol (ex-PENDIENTE)
A30: 46028 | B30: Enero | C30: MERCADO LIBRE | D30: 43389 | E30: Mercado Pago | F30: MERCADO LIBRE · gasto personal Sol
A31: 46030 | B31: Enero | C31: TRANSFERENCIAS | D31: 12426 | E31: Mercado Pago | F31: compra · gasto personal Sol (ex-PENDIENTE) · ex `Andres Javier Di Pasqua`
A32: 46030 | B32: Enero | C32: VESTIMENTA | D32: 395000 | E32: Mercado Pago | F32: ROPA · Ceferina · hoja Gasto Personal Sol
A33: 46030 | B33: Enero | C33: SALUD · Vitaminas | D33: 350000 | E33: Mercado Pago | F33: SALUD · Vitaminas · Promarine · gasto personal Sol
A34: 46031 | B34: Enero | C34: COMPRAS | D34: 44000 | E34: Mercado Pago | F34: COMPRAS · Catore · transferencia · gasto personal Sol (ex-PENDIENTE)
A35: 46107 | B35: Marzo | C35: PELUQUERÍA | D35: 75000 | E35: Mercado Pago | F35: PELUQUERÍA · Agustina Vissani (ex AGUS/PSA · ex CASA matriz 2026)
A36: 46129 | B36: Abril | C36: PELUQUERÍA | D36: 155000 | E36: Mercado Pago | F36: PELUQUERÍA · Agustina Vissani (ex AGUS/PSA · ex CASA matriz 2026)
A37: 46157 | B37: Mayo | C37: PELUQUERÍA | D37: 125000 | E37: Mercado Pago | F37: PELUQUERÍA · Agustina Vissani (ex AGUS/PSA · ex CASA matriz 2026)
... A336: 46176 | B336: Junio | C336: ROPA | D336: 284794 | E336: BBVA Visa | F336: ROPA · Pandora · ROPA / joyas · MERPAGO*PANDORA C.01/06 · gasto personal Sol
A337: 46183 | B337: Junio | C337: ROPA | E337: BBVA Mastercard · USD 3.807,01 (EUR 3.250) | F337: ROPA · gasto personal Sol · monto en USD (no convertido a ARS) · NO ES GASTO · consumo/compra USD BBVA Mastercard · ver hoja Sol Dollar Mdp
A338: 46140 | B338: Abril | C338: SUSCRIPCIONES · IA | D338: 275336 | E338: BBVA Visa · USD | F338: SUSCRIPCIONES · IA · Cursor · gasto personal Sol · USD 192.00 × TC MEP 1434.04 · suscripción · gasto personal Sol
A339: 46143 | B339: Mayo | C339: SUSCRIPCIONES · IA | D339: 28593 | E339: BBVA Visa · USD | F339: SUSCRIPCIONES · IA · Vercel · gasto personal Sol · USD 20.00 × TC MEP 1429.65 · suscripción · gasto personal Sol
...

Sheet Cashflow Compromisos
A1: Fuente | B1: Compra / Vencimiento | C1: Concepto | D1: Categoría | E1: Cuota | F1: De | G1: Monto (ARS) | H1: Mes | I1: Año-Mes | J1: Estado | K1: Comentario | L1: Responsable
A2: BBVA TC | B2: 45789 | C2: DIEGOJULIANKOZ | D2: Personal | E2: 1 | F2: 9 | G2: 84906 | H2: Mayo 2025 | I2: 2025-05 | J2: PAGADO | K2: C.01/09 · cashflow BBVA · gasto personal Sol | L2: Sol
A3: BBVA TC | B3: 45789 | C3: DIEGOJULIANKOZ | D3: Personal | E3: 2 | F3: 9 | G3: 84906 | H3: Junio 2025 | I3: 2025-06 | J3: PAGADO | K3: C.02/09 · cashflow BBVA · gasto personal Sol | L3: Sol
A4: BBVA TC | B4: 45827 | C4: ELCACOSMETICOSINC | D4: Personal | E4: 1 | F4: 9 | G4: 15054 | H4: Junio 2025 | I4: 2025-06 | J4: PAGADO | K4: C.01/09 · cashflow BBVA · gasto personal Sol | L4: Sol
A5: BBVA TC | B5: 45815 | C5: MONSERVO | D5: Personal | E5: 1 | F5: 9 | G5: 6665 | H5: Junio 2025 | I5: 2025-06 | J5: PAGADO | K5: C.01/09 · cashflow BBVA · gasto personal Sol | L5: Sol
A6: BBVA TC | B6: 45865 | C6: 3PRODUCTOS | D6: Personal | E6: 1 | F6: 9 | G6: 5445 | H6: Julio 2025 | I6: 2025-07 | J6: PAGADO | K6: C.01/09 · cashflow BBVA · gasto personal Sol | L6: Sol
A7: BBVA TC | B7: 45789 | C7: DIEGOJULIANKOZ | D7: Personal | E7: 3 | F7: 9 | G7: 84906 | H7: Julio 2025 | I7: 2025-07 | J7: PAGADO | K7: C.03/09 · cashflow BBVA · gasto personal Sol | L7: Sol
A8: BBVA TC | B8: 45827 | C8: ELCACOSMETICOSINC | D8: Personal | E8: 2 | F8: 9 | G8: 15054 | H8: Julio 2025 | I8: 2025-07 | J8: PAGADO | K8: C.02/09 · cashflow BBVA · gasto personal Sol | L8: Sol
A9: BBVA TC | B9: 45815 | C9: MONSERVO | D9: Personal | E9: 2 | F9: 9 | G9: 6665 | H9: Julio 2025 | I9: 2025-07 | J9: PAGADO | K9: C.02/09 · cashflow BBVA · gasto personal Sol | L9: Sol
A10: BBVA TC | B10: 45865 | C10: 3PRODUCTOS | D10: Personal | E10: 2 | F10: 9 | G10: 5445 | H10: Agosto 2025 | I10: 2025-08 | J10: PAGADO | K10: C.02/09 · cashflow BBVA · gasto personal Sol | L10: Sol
A11: BBVA TC | B11: 45789 | C11: DIEGOJULIANKOZ | D11: Personal | E11: 4 | F11: 9 | G11: 84906 | H11: Agosto 2025 | I11: 2025-08 | J11: PAGADO | K11: C.04/09 · cashflow BBVA · gasto personal Sol | L11: Sol
A12: BBVA TC | B12: 45827 | C12: ELCACOSMETICOSINC | D12: Personal | E12: 3 | F12: 9 | G12: 15054 | H12: Agosto 2025 | I12: 2025-08 | J12: PAGADO | K12: C.03/09 · cashflow BBVA · gasto personal Sol | L12: Sol
A13: BBVA TC | B13: 45890 | C13: JACKIESMITH | D13: Personal | E13: 1 | F13: 6 | G13: 10970 | H13: Agosto 2025 | I13: 2025-08 | J13: PAGADO | K13: C.01/06 · cashflow BBVA · gasto personal Sol | L13: Sol
... A253: AVA Fideicomiso | B253: 46300 | C253: AVA Palpa · cuota 11 · octubre 2026 | D253: AVA FIDEICOMISO | E253: 11 | F253: 32 | G253: 3275207 | H253: Octubre 2026 | I253: 2026-10 | J253: PENDIENTE | K253: 50% Sol de $6,550,413 · factura Cobranza 24/09 · TC MEP 1549.26 (02/10) · NO pagar duplicado en GPS hasta abonar | L253: Sol 50% (TBD)
A254: AVA Fideicomiso | B254: 46331 | C254: AVA Palpa · cuota 12 · pendiente factura | D254: AVA FIDEICOMISO | E254: 12 | F254: 32 | H254: Noviembre 2026 | I254: 2026-11 | J254: PENDIENTE | K254: Compromiso AVA · monto a confirmar · 50% Sol / 50% Chris | L254: Sol 50% (TBD)
A255: AVA Fideicomiso | B255: 46361 | C255: AVA Palpa · cuota 13 · pendiente factura | D255: AVA FIDEICOMISO | E255: 13 | F255: 32 | H255: Diciembre 2026 | I255: 2026-12 | J255: PENDIENTE | K255: Compromiso AVA · monto a confirmar · 50% Sol / 50% Chris | L255: Sol 50% (TBD)
A256: AVA Fideicomiso | B256: 46392 | C256: AVA Palpa · cuota 14 · pendiente factura | D256: AVA FIDEICOMISO | E256: 14 | F256: 32 | H256: Enero 2027 | I256: 2027-01 | J256: PENDIENTE | K256: Compromiso AVA · monto a confirmar · 50% Sol / 50% Chris | L256: Sol 50% (TBD)
A257: AVA Fideicomiso | B257: 46423 | C257: AVA Palpa · cuota 15 · pendiente factura | D257: AVA FIDEICOMISO | E257: 15 | F257: 32 | H257: Febrero 2027 | I257: 2027-02 | J257: PENDIENTE | K257: Compromiso AVA · monto a confirmar · 50% Sol / 50% Chris | L257: Sol 50% (TBD)
A258: AVA Fideicomiso | B258: 46451 | C258: AVA Palpa · cuota 16 · pendiente factura | D258: AVA FIDEICOMISO | E258: 16 | F258: 32 | H258: Marzo 2027 | I258: 2027-03 | J258: PENDIENTE | K258: Compromiso AVA · monto a confirmar · 50% Sol / 50% Chris | L258: Sol 50% (TBD)
A259: AVA Fideicomiso | B259: 46482 | C259: AVA Palpa · cuota 17 · pendiente factura | D259: AVA FIDEICOMISO | E259: 17 | F259: 32 | H259: Abril 2027 | I259: 2027-04 | J259: PENDIENTE | K259: Compromiso AVA · monto a confirmar · 50% Sol / 50% Chris | L259: Sol 50% (TBD)
A260: AVA Fideicomiso | B260: 46512 | C260: AVA Palpa · cuota 18 · pendiente factura | D260: AVA FIDEICOMISO | E260: 18 | F260: 32 | H260: Mayo 2027 | I260: 2027-05 | J260: PENDIENTE | K260: Compromiso AVA · monto a confirmar · 50% Sol / 50% Chris | L260: Sol 50% (TBD)
A261: AVA Fideicomiso | B261: 46543 | C261: AVA Palpa · cuota 19 · pendiente factura | D261: AVA FIDEICOMISO | E261: 19 | F261: 32 | H261: Junio 2027 | I261: 2027-06 | J261: PENDIENTE | K261: Compromiso AVA · monto a confirmar · 50% Sol / 50% Chris | L261: Sol 50% (TBD)
A262: AVA Fideicomiso | B262: 46573 | C262: AVA Palpa · cuota 20 · pendiente factura | D262: AVA FIDEICOMISO | E262: 20 | F262: 32 | H262: Julio 2027 | I262: 2027-07 | J262: PENDIENTE | K262: Compromiso AVA · monto a confirmar · 50% Sol / 50% Chris | L262: Sol 50% (TBD)
A263: AVA Fideicomiso | B263: 46604 | C263: AVA Palpa · cuota 21 · pendiente factura | D263: AVA FIDEICOMISO | E263: 21 | F263: 32 | H263: Agosto 2027 | I263: 2027-08 | J263: PENDIENTE | K263: Compromiso AVA · monto a confirmar · 50% Sol / 50% Chris | L263: Sol 50% (TBD)
A264: AVA Fideicomiso | B264: 46635 | C264: AVA Palpa · cuota 22 · pendiente factura | D264: AVA FIDEICOMISO | E264: 22 | F264: 32 | H264: Septiembre 2027 | I264: 2027-09 | J264: PENDIENTE | K264: Compromiso AVA · monto a confirmar · 50% Sol / 50% Chris | L264: Sol 50% (TBD)
A265: AVA Fideicomiso | B265: 46665 | C265: AVA Palpa · cuota 23 · pendiente factura | D265: AVA FIDEICOMISO | E265: 23 | F265: 32 | H265: Octubre 2027 | I265: 2027-10 | J265: PENDIENTE | K265: Compromiso AVA · monto a confirmar · 50% Sol / 50% Chris | L265: Sol 50% (TBD)
... A274: AVA Fideicomiso | B274: 46939 | C274: AVA Palpa · cuota 32 · pendiente factura | D274: AVA FIDEICOMISO | E274: 32 | F274: 32 | H274: Julio 2028 | I274: 2028-07 | J274: PENDIENTE | K274: Compromiso AVA · monto a confirmar · 50% Sol / 50% Chris | L274: Sol 50% (TBD)
A276: RESUMEN DE COMPROMISOS
A277: BBVA PAGADO | B277: 149 | C277: 9246803
A278: BBVA PENDIENTE a pagar | B278: 92 | C278: 9156618
A279: AVA Fideicomiso PAGADO (50% Sol) | B279: 10 | C279: 27859451
A280: AVA Fideicomiso PENDIENTE (cuotas futuras) | B280: 22 | C280: 3275207
A281: COMPROMISO NUMÉRICO ACTUAL (BBVA pendiente con monto) | B281: 92 | C281: 9156618
A282: Notas: AVA 50% Sol PAGADO ya está en Gasto Personal Sol (no duplicar). Cuota 11 factura conocida $6,550,413 (50% Sol $3,275,207) PENDIENTE de pago · vto 05/10/2026. Resúmenes oficiales prevalecen sobre texto de chat.

Sheet Sol Dollar Mdp
A1: Sol Dollar Mdp
A2: Stock de dólares de Sol. Las compras de dólar con BBVA Mastercard NO son gasto (no van a Gasto Personal Sol ni a la matriz 2026). Consumos USD de MC tampoco se imputan como gasto ARS. Percepciones USD (RG 5617 / IVA / IIBB) sí siguen en GPS.
A4: Saldo USD a la fecha | B4: 46295 | C4: 1.68 | D4: USD | E4: Resumen oficial tenencias USD MP · saldo final 1–30 sep = US$ 1,68 (detalle de movimientos del PDF cierra en 2002,21 → ajuste REVISAR)
A6: Detalle de movimientos
A7: Fecha | B7: Tipo | C7: Origen | D7: Descripción | E7: USD | F7: TC MEP | G7: ARS informativo (no es gasto) | H7: Saldo USD | I7: Comentario
A8: 46266 | B8: Saldo inicial | C8: Tenencias MP | D8: Stock USD inicio septiembre | E8: 3159.41 | H8: 3159.41 | I8: Saldo inicial oficial tenencias USD
A9: 46266 | B9: Rendimiento | C9: Mercado Pago | D9: Rendimientos USD | E9: 0.06 | H9: 3159.47 | I9: Tenencias USD · resumen oficial cuenta MP 1–30 sep 2026
A10: 46266 | B10: Venta | C10: Mercado Pago | D10: Venta de dólar MEP | E10: -1135.23 | F10: 1511.25 | G10: 1715612 | H10: 2024.24 | I10: Venta MEP · US$ -1.135,23 · ARS ceil 1.715.611,40 · resumen oficial cuenta MP 1–30 sep 2026
A11: 46272 | B11: Entrada | C11: Mercado Pago | D11: Dinero retirado Gastos (USD) | E11: 2001.2 | H11: 4025.44 | I11: Dinero retirado Gastos US$ 2.001,20 · resumen oficial cuenta MP 1–30 sep 2026
A12: 46273 | B12: Rendimiento | C12: Mercado Pago | D12: Rendimientos USD | E12: 0.1 | H12: 4025.54 | I12: Tenencias USD · resumen oficial cuenta MP 1–30 sep 2026
A13: 46274 | B13: Rendimiento | C13: Mercado Pago | D13: Rendimientos USD | E13: 0.1 | H13: 4025.64 | I13: Tenencias USD · resumen oficial cuenta MP 1–30 sep 2026
A14: 46275 | B14: Rendimiento | C14: Mercado Pago | D14: Rendimientos USD | E14: 0.1 | H14: 4025.74 | I14: Tenencias USD · resumen oficial cuenta MP 1–30 sep 2026
A15: 46275 | B15: Venta | C15: Mercado Pago | D15: Venta de dólar MEP | E15: -1984.17 | F15: 1506.78 | G15: 2989714 | H15: 2041.57 | I15: Venta MEP · US$ -1.984,17 · ARS ceil 2.989.713,19 · resumen oficial cuenta MP 1–30 sep 2026
A16: 46280 | B16: Rendimiento | C16: Mercado Pago | D16: Rendimientos USD | E16: 0.01 | H16: 2041.58 | I16: Tenencias USD · resumen oficial cuenta MP 1–30 sep 2026
A17: 46280 | B17: Venta | C17: Mercado Pago | D17: Venta de dólar MEP | E17: -39.37 | F17: 1507.08 | G17: 59334 | H17: 2002.21 | I17: Venta MEP · US$ -39,37 · ARS ceil 59.333,83 · resumen oficial cuenta MP 1–30 sep 2026
A18: 46295 | B18: Ajuste | C18: Tenencias MP | D18: Ajuste a saldo final oficial | E18: -2000.53 | H18: 1.68 | I18: REVISAR · detalle PDF termina en US$ 2002,21 pero saldo final del resumen = US$ 1,68 · resumen oficial cuenta MP 1–30 sep 2026
A20: Consumos USD Mastercard excluidos de GPS (no mueven el stock; stock = US$ 1,68 al 30/09)
A21: Fecha GPS | B21: Concepto | C21: USD / nota | D21: ARS que se sacó de GPS | E21: Medio
A22: 46183 | B22: ROPA | C22: ROPA · gasto personal Sol · monto en USD (no convertido a AR | E22: BBVA Mastercard · USD 3.807,01 (EUR 3.250)
A23: 46163 | B23: SUSCRIPCIONES · IA | C23: 20 | D23: 28593 | E23: BBVA Mastercard · USD
A24: 46163 | B24: SUSCRIPCIONES · IA | C24: 30 | D24: 42890 | E24: BBVA Mastercard · USD
A25: 46194 | B25: SUSCRIPCIONES · IA | C25: 30 | D25: 43740 | E25: BBVA Mastercard · USD
A26: 46029 | B26: SUSCRIPCIONES · IA | C26: 19.99 | D26: 30110 | E26: BBVA Mastercard · USD
A27: 46060 | B27: SUSCRIPCIONES · IA | C27: 19.99 | D27: 29193 | E27: BBVA Mastercard · USD
A28: 46088 | B28: SUSCRIPCIONES · IA | C28: 19.99 | D28: 28668 | E28: BBVA Mastercard · USD
A29: 46119 | B29: SUSCRIPCIONES · IA | C29: 19.99 | D29: 28667 | E29: BBVA Mastercard · USD
A30: 46057 | B30: SUSCRIPCIONES · IA | C30: SUSCRIPCIONES · IA · ChatGPT / OpenAI · gasto personal Sol | D30: 29208 | E30: BBVA
A31: 46081 | B31: SUSCRIPCIONES · IA | C31: SUSCRIPCIONES · IA · ChatGPT / OpenAI · gasto personal Sol | D31: 29208 | E31: BBVA
A32: 46117 | B32: SUSCRIPCIONES · IA | C32: SUSCRIPCIONES · IA · ChatGPT / OpenAI · gasto personal Sol | D32: 28681 | E32: BBVA
